Workbook

Sheet Tabelas Auxiliares
A1: Município | B1: Regional | C1: Valor coffee break
A2: Abatiá | B2: Cornélio Procópio | C2: =IF(B2="Apucarana",22.64,(IF(B2="Campo Mourão",22.64,IF(B2="Cascavel",22.64,IF(B2="Cianorte",22.64,IF(B2="Cornélio Procópio",22.64,IF(B2="Curitiba",22.64,IF(B2="Dois Vizinhos",22.64,IF(B2="Francisco Beltrão",21.33,IF(B2="Guarapuava",22.64,IF(B2="Irati",22.64,IF(B2="Ivaiporã",19.95,IF(B2="Laranjeiras do Sul",22.64,IF(B2="Londrina",22.64,IF(B2="Maringá",22.64,IF(B2="Paranaguá",20.63,IF(B2="Paranavaí",22.64,IF(B2="Pato Branco",22,IF(B2="Ponta Grossa",22.64,IF(B2="Santo Antônio da Platina",21.58,IF(B2="Toledo",22.64,IF(B2="Umuarama",22.64,IF(B2="União da Vitória",22.64,0))))))))))))))))))))))) -> 22.64
A3: Adrianópolis | B3: Curitiba | C3: =IF(B3="Apucarana",22.64,(IF(B3="Campo Mourão",22.64,IF(B3="Cascavel",22.64,IF(B3="Cianorte",22.64,IF(B3="Cornélio Procópio",22.64,IF(B3="Curitiba",22.64,IF(B3="Dois Vizinhos",22.64,IF(B3="Francisco Beltrão",21.33,IF(B3="Guarapuava",22.64,IF(B3="Irati",22.64,IF(B3="Ivaiporã",19.95,IF(B3="Laranjeiras do Sul",22.64,IF(B3="Londrina",22.64,IF(B3="Maringá",22.64,IF(B3="Paranaguá",20.63,IF(B3="Paranavaí",22.64,IF(B3="Pato Branco",22,IF(B3="Ponta Grossa",22.64,IF(B3="Santo Antônio da Platina",21.58,IF(B3="Toledo",22.64,IF(B3="Umuarama",22.64,IF(B3="União da Vitória",22.64,0))))))))))))))))))))))) -> 22.64
A4: Agudos do Sul | B4: Curitiba | C4: =IF(B4="Apucarana",22.64,(IF(B4="Campo Mourão",22.64,IF(B4="Cascavel",22.64,IF(B4="Cianorte",22.64,IF(B4="Cornélio Procópio",22.64,IF(B4="Curitiba",22.64,IF(B4="Dois Vizinhos",22.64,IF(B4="Francisco Beltrão",21.33,IF(B4="Guarapuava",22.64,IF(B4="Irati",22.64,IF(B4="Ivaiporã",19.95,IF(B4="Laranjeiras do Sul",22.64,IF(B4="Londrina",22.64,IF(B4="Maringá",22.64,IF(B4="Paranaguá",20.63,IF(B4="Paranavaí",22.64,IF(B4="Pato Branco",22,IF(B4="Ponta Grossa",22.64,IF(B4="Santo Antônio da Platina",21.58,IF(B4="Toledo",22.64,IF(B4="Umuarama",22.64,IF(B4="União da Vitória",22.64,0))))))))))))))))))))))) -> 22.64
A5: Almirante Tamandaré | B5: Curitiba | C5: =IF(B5="Apucarana",22.64,(IF(B5="Campo Mourão",22.64,IF(B5="Cascavel",22.64,IF(B5="Cianorte",22.64,IF(B5="Cornélio Procópio",22.64,IF(B5="Curitiba",22.64,IF(B5="Dois Vizinhos",22.64,IF(B5="Francisco Beltrão",21.33,IF(B5="Guarapuava",22.64,IF(B5="Irati",22.64,IF(B5="Ivaiporã",19.95,IF(B5="Laranjeiras do Sul",22.64,IF(B5="Londrina",22.64,IF(B5="Maringá",22.64,IF(B5="Paranaguá",20.63,IF(B5="Paranavaí",22.64,IF(B5="Pato Branco",22,IF(B5="Ponta Grossa",22.64,IF(B5="Santo Antônio da Platina",21.58,IF(B5="Toledo",22.64,IF(B5="Umuarama",22.64,IF(B5="União da Vitória",22.64,0))))))))))))))))))))))) -> 22.64
A6: Altamira do Paraná | B6: Campo Mourão | C6: =IF(B6="Apucarana",22.64,(IF(B6="Campo Mourão",22.64,IF(B6="Cascavel",22.64,IF(B6="Cianorte",22.64,IF(B6="Cornélio Procópio",22.64,IF(B6="Curitiba",22.64,IF(B6="Dois Vizinhos",22.64,IF(B6="Francisco Beltrão",21.33,IF(B6="Guarapuava",22.64,IF(B6="Irati",22.64,IF(B6="Ivaiporã",19.95,IF(B6="Laranjeiras do Sul",22.64,IF(B6="Londrina",22.64,IF(B6="Maringá",22.64,IF(B6="Paranaguá",20.63,IF(B6="Paranavaí",22.64,IF(B6="Pato Branco",22,IF(B6="Ponta Grossa",22.64,IF(B6="Santo Antônio da Platina",21.58,IF(B6="Toledo",22.64,IF(B6="Umuarama",22.64,IF(B6="União da Vitória",22.64,0))))))))))))))))))))))) -> 22.64
A7: Alto Paraíso | B7: Umuarama | C7: =IF(B7="Apucarana",22.64,(IF(B7="Campo Mourão",22.64,IF(B7="Cascavel",22.64,IF(B7="Cianorte",22.64,IF(B7="Cornélio Procópio",22.64,IF(B7="Curitiba",22.64,IF(B7="Dois Vizinhos",22.64,IF(B7="Francisco Beltrão",21.33,IF(B7="Guarapuava",22.64,IF(B7="Irati",22.64,IF(B7="Ivaiporã",19.95,IF(B7="Laranjeiras do Sul",22.64,IF(B7="Londrina",22.64,IF(B7="Maringá",22.64,IF(B7="Paranaguá",20.63,IF(B7="Paranavaí",22.64,IF(B7="Pato Branco",22,IF(B7="Ponta Grossa",22.64,IF(B7="Santo Antônio da Platina",21.58,IF(B7="Toledo",22.64,IF(B7="Umuarama",22.64,IF(B7="União da Vitória",22.64,0))))))))))))))))))))))) -> 22.64
A8: Alto Paraná | B8: Paranavaí | C8: =IF(B8="Apucarana",22.64,(IF(B8="Campo Mourão",22.64,IF(B8="Cascavel",22.64,IF(B8="Cianorte",22.64,IF(B8="Cornélio Procópio",22.64,IF(B8="Curitiba",22.64,IF(B8="Dois Vizinhos",22.64,IF(B8="Francisco Beltrão",21.33,IF(B8="Guarapuava",22.64,IF(B8="Irati",22.64,IF(B8="Ivaiporã",19.95,IF(B8="Laranjeiras do Sul",22.64,IF(B8="Londrina",22.64,IF(B8="Maringá",22.64,IF(B8="Paranaguá",20.63,IF(B8="Paranavaí",22.64,IF(B8="Pato Branco",22,IF(B8="Ponta Grossa",22.64,IF(B8="Santo Antônio da Platina",21.58,IF(B8="Toledo",22.64,IF(B8="Umuarama",22.64,IF(B8="União da Vitória",22.64,0))))))))))))))))))))))) -> 22.64
A9: Alto Piquiri | B9: Umuarama | C9: =IF(B9="Apucarana",22.64,(IF(B9="Campo Mourão",22.64,IF(B9="Cascavel",22.64,IF(B9="Cianorte",22.64,IF(B9="Cornélio Procópio",22.64,IF(B9="Curitiba",22.64,IF(B9="Dois Vizinhos",22.64,IF(B9="Francisco Beltrão",21.33,IF(B9="Guarapuava",22.64,IF(B9="Irati",22.64,IF(B9="Ivaiporã",19.95,IF(B9="Laranjeiras do Sul",22.64,IF(B9="Londrina",22.64,IF(B9="Maringá",22.64,IF(B9="Paranaguá",20.63,IF(B9="Paranavaí",22.64,IF(B9="Pato Branco",22,IF(B9="Ponta Grossa",22.64,IF(B9="Santo Antônio da Platina",21.58,IF(B9="Toledo",22.64,IF(B9="Umuarama",22.64,IF(B9="União da Vitória",22.64,0))))))))))))))))))))))) -> 22.64
A10: Altônia | B10: Umuarama | C10: =IF(B10="Apucarana",22.64,(IF(B10="Campo Mourão",22.64,IF(B10="Cascavel",22.64,IF(B10="Cianorte",22.64,IF(B10="Cornélio Procópio",22.64,IF(B10="Curitiba",22.64,IF(B10="Dois Vizinhos",22.64,IF(B10="Francisco Beltrão",21.33,IF(B10="Guarapuava",22.64,IF(B10="Irati",22.64,IF(B10="Ivaiporã",19.95,IF(B10="Laranjeiras do Sul",22.64,IF(B10="Londrina",22.64,IF(B10="Maringá",22.64,IF(B10="Paranaguá",20.63,IF(B10="Paranavaí",22.64,IF(B10="Pato Branco",22,IF(B10="Ponta Grossa",22.64,IF(B10="Santo Antônio da Platina",21.58,IF(B10="Toledo",22.64,IF(B10="Umuarama",22.64,IF(B10="União da Vitória",22.64,0))))))))))))))))))))))) -> 22.64
A11: Alvorada do Sul | B11: Londrina | C11: =IF(B11="Apucarana",22.64,(IF(B11="Campo Mourão",22.64,IF(B11="Cascavel",22.64,IF(B11="Cianorte",22.64,IF(B11="Cornélio Procópio",22.64,IF(B11="Curitiba",22.64,IF(B11="Dois Vizinhos",22.64,IF(B11="Francisco Beltrão",21.33,IF(B11="Guarapuava",22.64,IF(B11="Irati",22.64,IF(B11="Ivaiporã",19.95,IF(B11="Laranjeiras do Sul",22.64,IF(B11="Londrina",22.64,IF(B11="Maringá",22.64,IF(B11="Paranaguá",20.63,IF(B11="Paranavaí",22.64,IF(B11="Pato Branco",22,IF(B11="Ponta Grossa",22.64,IF(B11="Santo Antônio da Platina",21.58,IF(B11="Toledo",22.64,IF(B11="Umuarama",22.64,IF(B11="União da Vitória",22.64,0))))))))))))))))))))))) -> 22.64
A12: Amaporã | B12: Paranavaí | C12: =IF(B12="Apucarana",22.64,(IF(B12="Campo Mourão",22.64,IF(B12="Cascavel",22.64,IF(B12="Cianorte",22.64,IF(B12="Cornélio Procópio",22.64,IF(B12="Curitiba",22.64,IF(B12="Dois Vizinhos",22.64,IF(B12="Francisco Beltrão",21.33,IF(B12="Guarapuava",22.64,IF(B12="Irati",22.64,IF(B12="Ivaiporã",19.95,IF(B12="Laranjeiras do Sul",22.64,IF(B12="Londrina",22.64,IF(B12="Maringá",22.64,IF(B12="Paranaguá",20.63,IF(B12="Paranavaí",22.64,IF(B12="Pato Branco",22,IF(B12="Ponta Grossa",22.64,IF(B12="Santo Antônio da Platina",21.58,IF(B12="Toledo",22.64,IF(B12="Umuarama",22.64,IF(B12="União da Vitória",22.64,0))))))))))))))))))))))) -> 22.64
A13: Ampére | B13: Francisco Beltrão | C13: =IF(B13="Apucarana",22.64,(IF(B13="Campo Mourão",22.64,IF(B13="Cascavel",22.64,IF(B13="Cianorte",22.64,IF(B13="Cornélio Procópio",22.64,IF(B13="Curitiba",22.64,IF(B13="Dois Vizinhos",22.64,IF(B13="Francisco Beltrão",21.33,IF(B13="Guarapuava",22.64,IF(B13="Irati",22.64,IF(B13="Ivaiporã",19.95,IF(B13="Laranjeiras do Sul",22.64,IF(B13="Londrina",22.64,IF(B13="Maringá",22.64,IF(B13="Paranaguá",20.63,IF(B13="Paranavaí",22.64,IF(B13="Pato Branco",22,IF(B13="Ponta Grossa",22.64,IF(B13="Santo Antônio da Platina",21.58,IF(B13="Toledo",22.64,IF(B13="Umuarama",22.64,IF(B13="União da Vitória",22.64,0))))))))))))))))))))))) -> 21.33
... A400: Xambrê | B400: Umuarama | C400: =IF(B400="Apucarana",22.64,(IF(B400="Campo Mourão",22.64,IF(B400="Cascavel",22.64,IF(B400="Cianorte",22.64,IF(B400="Cornélio Procópio",22.64,IF(B400="Curitiba",22.64,IF(B400="Dois Vizinhos",22.64,IF(B400="Francisco Beltrão",21.33,IF(B400="Guarapuava",22.64,IF(B400="Irati",22.64,IF(B400="Ivaiporã",19.95,IF(B400="Laranjeiras do Sul",22.64,IF(B400="Londrina",22.64,IF(B400="Maringá",22.64,IF(B400="Paranaguá",20.63,IF(B400="Paranavaí",22.64,IF(B400="Pato Branco",22,IF(B400="Ponta Grossa",22.64,IF(B400="Santo Antônio da Platina",21.58,IF(B400="Toledo",22.64,IF(B400="Umuarama",22.64,IF(B400="União da Vitória",22.64,0))))))))))))))))))))))) -> 22.64

Sheet Respostas ao formulário 1
A1: n° | B1: Carimbo de data/hora | C1: Endereço de e-mail | D1: Status | E1: Diretoria | F1: Departamento | G1: Informe a Assessoria/Regional/Polo/Estação Responsável | H1: N° SAF | I1: Informar título da Capacitação | J1: Metodologia da Capacitação | K1: N° de participantes do IDR-Paraná | L1: Informar nome dos participantes (se houver) | M1: Instituição parceira | N1: N° participantes externos | O1: Informe o Estado onde ocorrerá a capacitação | P1: Informar município onde ocorrerá a capacitação | Q1: Data de Início | R1: Data de Término | S1: A data informada é definitiva? | T1: Modalidade | U1: Temática Básica | V1: Justificativa | W1: Informar quantidade de refeição (n°) | X1: Informar quantidade de pernoite (n°) | Y1: Taxa de Inscrição (R$) | Z1: Material Gráfico (R$) | AA1: Passagem aérea (R$) | AB1: Passagem terrestre/ônibus | AC1: Táxi (R$) | AD1: Pedágio (R$) | AE1: Van (R$) | AF1: Coffee Break | AG1: Total KM (Veículo oficial) | AH1: Integração | AI1: Valor Coffee break (R$) | AJ1: Valor Total Combustível (R$) | AK1: Valor Total Diárias (R$) | AL1: Valor Total IDR-Paraná (R$) | AM1: Parecer do Departamento | AN1: Parecer da Diretoria
A2: =ROW(A2)-1 -> 1 | B2: 45999.677 | C2: tpellini@idr.pr.gov.br | D2: A aprovar | E2: =VLOOKUP(G2,DiretoriaDepart.Coord.!$A$1:$C$72,2,FALSE) -> Pesquisa e Inovação | F2: =VLOOKUP(G2,DiretoriaDepart.Coord.!$A$1:$C$72,3,FALSE) -> Pesquisa e Capacitação | G2: Socioeconomia e Métodos Quantitativos (Pesquisa) | I2: XVI Encontro Nacional da Sociedade Brasileira de Economia Ecológica (ECOECO) | J2: Encontro | K2: 1 | L2: Tiago Santos Telles | M2: Sociedade Brasileira de Economia Ecológica – ECOECO. | N2: 150 | O2: Alagoas | P2: Maceió | Q2: 45998.333 | R2: 46003.75 | S2: Não | T2: Presencial | U2: Economia ecológica. | V2: A participação é essencial para aprofundar conhecimentos e fortalecer pesquisas voltadas à integração entre economia e ecologia, áreas estratégicas para o desenvolvimento sustentável da agropecuária. O evento possibilita atualização científica sobre abordagens inovadoras em economia ecológica, análise de serviços ecossistêmicos e políticas públicas ambientais, além de promover a troca de experiências com pesquisadores nacionais e internacionais. Essa interação contribui para aprimorar metodologias aplicadas em estudos sobre sustentabilidade, uso eficiente de recursos naturais e impactos socioeconômicos, alinhando-se às metas institucionais de geração de conhecimento e suporte à tomada de decisão para sistemas produtivos mais resilientes. | W2: 12 | X2: 6 | Y2: 350 | Z2: 0 | AA2: 1650 | AB2: 0 | AC2: 300 | AD2: 0 | AE2: 0 | AF2: Não | AG2: 0 | AH2: Não | AI2: =IF(AF2="Sim",INT((R2-Q2+1))*K2*VLOOKUP(P2,'Tabelas Auxiliares'!$A$1:$C$400,3,FALSE),0) -> 0 | AJ2: =(AG2/10)*7 -> 0 | AK2: =IFS( O2="Acre",((W2*0.15)+(X2*0.7))*VLOOKUP(P2,'MunicípiosEstados'!$A$2:$B$23,2,FALSE), O2="Alagoas",((W2*0.15)+(X2*0.7))*VLOOKUP(P2,'MunicípiosEstados'!$C$2:$D$103,2,FALSE), O2="Amapá",((W2*0.15)+(X2*0.7))*VLOOKUP(P2,'MunicípiosEstados'!$E$2:$F$17,2,FALSE), O2="Amazonas",((W2*0.15)+(X2*0.7))*VLOOKUP(P2,'MunicípiosEstados'!$G$2:$H$63,2,FALSE), O2="Bahia",((W2*0.15)+(X2*0.7))*VLOOKUP(P2,'MunicípiosEstados'!$I$2:$J$418,2,FALSE), O2="Ceará",((W2*0.15)+(X2*0.7))*VLOOKUP(P2,'MunicípiosEstados'!$K$2:$L$185,2,FALSE), O2="Distrito Federal",((W2*0.15)+(X2*0.7))*VLOOKUP(P2,'MunicípiosEstados'!$M$2:$N$2,2,FALSE), O2="Espírito Santo",((W2*0.15)+(X2*0.7))*VLOOKUP(P2,'MunicípiosEstados'!$O$2:$P$79,2,FALSE), O2="Goiás",((W2*0.15)+(X2*0.7))*VLOOKUP(P2,'MunicípiosEstados'!$Q$2:$R$247,2,FALSE), O2="Maranhão",((W2*0.15)+(X2*0.7))*VLOOKUP(P2,'MunicípiosEstados'!$S$2:$T$218,2,FALSE), O2="Mato Grosso",((W2*0.15)+(X2*0.7))*VLOOKUP(P2,'MunicípiosEstados'!$U$2:$V$143,2,FALSE), O2="Mato Grosso do Sul",((W2*0.15)+(X2*0.7))*VLOOKUP(P2,'MunicípiosEstados'!$W$2:$X$80,2,FALSE), O2="Minas Gerais",((W2*0.15)+(X2*0.7))*VLOOKUP(P2,'MunicípiosEstados'!$Y$2:$Z$854,2,FALSE), O2="Pará",((W2*0.15)+(X2*0.7))*VLOOKUP(P2,'MunicípiosEstados'!$AA$2:$AB$145,2,FALSE), O2="Paraíba",((W2*0.15)+(X2*0.7))*VLOOKUP(P2,'MunicípiosEstados'!$AC$2:$AD$224,2,FALSE), O2="Paraná",((W2*0.15)+(X2*0.7))*VLOOKUP(P2,'MunicípiosEstados'!$AE$2:$AF$400,2,FALSE), O2="Pernambuco",((W2*0.15)+(X2*0.7))*VLOOKUP(P2,'MunicípiosEstados'!$AG$2:$AH$186,2,FALSE), O2="Piauí",((W2*0.15)+(X2*0.7))*VLOOKUP(P2,'MunicípiosEstados'!$AI$2:$AJ$225,2,FALSE), O2="Rio Grande do Norte",((W2*0.15)+(X2*0.7))*VLOOKUP(P2,'MunicípiosEstados'!$AK$2:$AL$168,2,FALSE), O2="Rio Grande do Sul",((W2*0.15)+(X2*0.7))*VLOOKUP(P2,'MunicípiosEstados'!$AM$2:$AN$498,2,FALSE), O2="Rio de Janeiro",((W2*0.15)+(X2*0.7))*VLOOKUP(P2,'MunicípiosEstados'!$AO$2:$AP$93,2,FALSE), O2="Rondônia",((W2*0.15)+(X2*0.7))*VLOOKUP(P2,'MunicípiosEstados'!$AQ$2:$AR$53,2,FALSE), O2="Roraima",((W2*0.15)+(X2*0.7))*VLOOKUP(P2,'MunicípiosEstados'!$AS$2:$AT$16,2,FALSE), O2="Santa Catarina",((W2*0.15)+(X2*0.7))*VLOOKUP(P2,'MunicípiosEstados'!$AU$2:$AV$296,2,FALSE), O2="São Paulo",((W2*0.15)+(X2*0.7))*VLOOKUP(P2,'MunicípiosEstados'!$AW$2:$AX$646,2,FALSE), O2="Sergipe",((W2*0.15)+(X2*0.7))*VLOOKUP(P2,'MunicípiosEstados'!$AY$2:$AZ$76,2,FALSE), O2="Tocantins",((W2*0.15)+(X2*0.7))*VLOOKUP(P2,'MunicípiosEstados'!$BA$2:$BB$140,2,FALSE), O2="Exterior",((W2*0.15)+(X2*0.7))*VLOOKUP(P2,'MunicípiosEstados'!$BC$2:$BE$221,3,FALSE),TRUE,0 ) -> 2227.56 | AL2: =AK2+AJ2+AI2+AE2+AD2+AC2+AB2+AA2+Z2+Y2 -> 4527.56
A3: =ROW(A3)-1 -> 2 | B3: 45993.395 | C3: graziela_barbosa@idr.pr.gov.br | D3: Aprovado | E3: =VLOOKUP(G3,DiretoriaDepart.Coord.!$A$1:$C$72,2,FALSE) -> Pesquisa e Inovação | F3: =VLOOKUP(G3,DiretoriaDepart.Coord.!$A$1:$C$72,3,FALSE) -> Inovação e Comunicação Científica | G3: Solos e Meio Ambiente (Pesquisa) | I3: IV Simpósio Brasileiro de Solos Arenosos | J3: Simpósio | K3: 1 | L3: Jonez Fidalski | M3: Não se aplica | N3: 1 | O3: Bahia | P3: Luís Eduardo Magalhães | Q3: 45901.333 | R3: 45903.708 | S3: Sim | T3: Presencial | U3: Sistemas de produção resilientes em solos leves | V3: 01) Atualizações de manejo do solos e da água em solos arenosos no Brasil, participar da Comissão Organizadora; 2) submeter um resumo. | W3: 10 | X3: 5 | Y3: 1000 | Z3: 250 | AA3: 4500 | AB3: 0 | AC3: 500 | AD3: 0 | AE3: 0 | AF3: Não | AG3: 0 | AH3: Não | AI3: =IF(AF3="Sim",INT((R3-Q3+1))*K3*VLOOKUP(P3,'Tabelas Auxiliares'!$A$1:$C$400,3,FALSE),0) -> 0 | AJ3: =(AG3/10)*7 -> 0 | AK3: =IFS( O3="Acre",((W3*0.15)+(X3*0.7))*VLOOKUP(P3,'MunicípiosEstados'!$A$2:$B$23,2,FALSE), O3="Alagoas",((W3*0.15)+(X3*0.7))*VLOOKUP(P3,'MunicípiosEstados'!$C$2:$D$103,2,FALSE), O3="Amapá",((W3*0.15)+(X3*0.7))*VLOOKUP(P3,'MunicípiosEstados'!$E$2:$F$17,2,FALSE), O3="Amazonas",((W3*0.15)+(X3*0.7))*VLOOKUP(P3,'MunicípiosEstados'!$G$2:$H$63,2,FALSE), O3="Bahia",((W3*0.15)+(X3*0.7))*VLOOKUP(P3,'MunicípiosEstados'!$I$2:$J$418,2,FALSE), O3="Ceará",((W3*0.15)+(X3*0.7))*VLOOKUP(P3,'MunicípiosEstados'!$K$2:$L$185,2,FALSE), O3="Distrito Federal",((W3*0.15)+(X3*0.7))*VLOOKUP(P3,'MunicípiosEstados'!$M$2:$N$2,2,FALSE), O3="Espírito Santo",((W3*0.15)+(X3*0.7))*VLOOKUP(P3,'MunicípiosEstados'!$O$2:$P$79,2,FALSE), O3="Goiás",((W3*0.15)+(X3*0.7))*VLOOKUP(P3,'MunicípiosEstados'!$Q$2:$R$247,2,FALSE), O3="Maranhão",((W3*0.15)+(X3*0.7))*VLOOKUP(P3,'MunicípiosEstados'!$S$2:$T$218,2,FALSE), O3="Mato Grosso",((W3*0.15)+(X3*0.7))*VLOOKUP(P3,'MunicípiosEstados'!$U$2:$V$143,2,FALSE), O3="Mato Grosso do Sul",((W3*0.15)+(X3*0.7))*VLOOKUP(P3,'MunicípiosEstados'!$W$2:$X$80,2,FALSE), O3="Minas Gerais",((W3*0.15)+(X3*0.7))*VLOOKUP(P3,'MunicípiosEstados'!$Y$2:$Z$854,2,FALSE), O3="Pará",((W3*0.15)+(X3*0.7))*VLOOKUP(P3,'MunicípiosEstados'!$AA$2:$AB$145,2,FALSE), O3="Paraíba",((W3*0.15)+(X3*0.7))*VLOOKUP(P3,'MunicípiosEstados'!$AC$2:$AD$224,2,FALSE), O3="Paraná",((W3*0.15)+(X3*0.7))*VLOOKUP(P3,'MunicípiosEstados'!$AE$2:$AF$400,2,FALSE), O3="Pernambuco",((W3*0.15)+(X3*0.7))*VLOOKUP(P3,'MunicípiosEstados'!$AG$2:$AH$186,2,FALSE), O3="Piauí",((W3*0.15)+(X3*0.7))*VLOOKUP(P3,'MunicípiosEstados'!$AI$2:$AJ$225,2,FALSE), O3="Rio Grande do Norte",((W3*0.15)+(X3*0.7))*VLOOKUP(P3,'MunicípiosEstados'!$AK$2:$AL$168,2,FALSE), O3="Rio Grande do Sul",((W3*0.15)+(X3*0.7))*VLOOKUP(P3,'MunicípiosEstados'!$AM$2:$AN$498,2,FALSE), O3="Rio de Janeiro",((W3*0.15)+(X3*0.7))*VLOOKUP(P3,'MunicípiosEstados'!$AO$2:$AP$93,2,FALSE), O3="Rondônia",((W3*0.15)+(X3*0.7))*VLOOKUP(P3,'MunicípiosEstados'!$AQ$2:$AR$53,2,FALSE), O3="Roraima",((W3*0.15)+(X3*0.7))*VLOOKUP(P3,'MunicípiosEstados'!$AS$2:$AT$16,2,FALSE), O3="Santa Catarina",((W3*0.15)+(X3*0.7))*VLOOKUP(P3,'MunicípiosEstados'!$AU$2:$AV$296,2,FALSE), O3="São Paulo",((W3*0.15)+(X3*0.7))*VLOOKUP(P3,'MunicípiosEstados'!$AW$2:$AX$646,2,FALSE), O3="Sergipe",((W3*0.15)+(X3*0.7))*VLOOKUP(P3,'MunicípiosEstados'!$AY$2:$AZ$76,2,FALSE), O3="Tocantins",((W3*0.15)+(X3*0.7))*VLOOKUP(P3,'MunicípiosEstados'!$BA$2:$BB$140,2,FALSE), O3="Exterior",((W3*0.15)+(X3*0.7))*VLOOKUP(P3,'MunicípiosEstados'!$BC$2:$BE$221,3,FALSE),TRUE,0 ) -> 1452.75 | AL3: =AK3+AJ3+AI3+AE3+AD3+AC3+AB3+AA3+Z3+Y3 -> 7702.75 | AN3: Aprovado para Jonez Fidalski
A4: =ROW(A4)-1 -> 3 | B4: 45979.577 | C4: santosjb@idr.pr.gov.br | D4: A aprovar | E4: =VLOOKUP(G4,DiretoriaDepart.Coord.!$A$1:$C$72,2,FALSE) -> Pesquisa e Inovação | F4: =VLOOKUP(G4,DiretoriaDepart.Coord.!$A$1:$C$72,3,FALSE) -> Inovação e Comunicação Científica | G4: Solos e Meio Ambiente (Pesquisa) | I4: 20° Encontro Nacional do Sistema Plantio Direto e 3° Encontro Mundial do Sistema Plantio Direto | J4: Encontro | K4: 1 | L4: Josiane Burkner dos Santos | M4: FEBRAPDP | N4: 0 | O4: Distrito Federal | P4: Brasília | Q4: 45845.333 | R4: 45847.708 | S4: Sim | T4: Presencial | U4: Sistema Plantio Direto | V4: Manter a visibilidade do IDR-Paraná como instituição que conduziu e conduz o Paraná como o estado com maior produtividade e sustentabilidade exatamente por essa instituição ter escolhido desde os anos 80 o fomento da prática do SPD, é muito importante para continuarmos sendo reconhecidos como uma empresa que gera pesquisa de qualidade para o mundo. | W4: 10 | X4: 4 | Y4: 800 | Z4: 350 | AA4: 4500 | AB4: 500 | AC4: 1000 | AD4: 0 | AE4: 500 | AF4: Não | AG4: 500 | AH4: Sim | AI4: =IF(AF4="Sim",INT((R4-Q4+1))*K4*VLOOKUP(P4,'Tabelas Auxiliares'!$A$1:$C$400,3,FALSE),0) -> 0 | AJ4: =(AG4/10)*7 -> 350 | AK4: =IFS( O4="Acre",((W4*0.15)+(X4*0.7))*VLOOKUP(P4,'MunicípiosEstados'!$A$2:$B$23,2,FALSE), O4="Alagoas",((W4*0.15)+(X4*0.7))*VLOOKUP(P4,'MunicípiosEstados'!$C$2:$D$103,2,FALSE), O4="Amapá",((W4*0.15)+(X4*0.7))*VLOOKUP(P4,'MunicípiosEstados'!$E$2:$F$17,2,FALSE), O4="Amazonas",((W4*0.15)+(X4*0.7))*VLOOKUP(P4,'MunicípiosEstados'!$G$2:$H$63,2,FALSE), O4="Bahia",((W4*0.15)+(X4*0.7))*VLOOKUP(P4,'MunicípiosEstados'!$I$2:$J$418,2,FALSE), O4="Ceará",((W4*0.15)+(X4*0.7))*VLOOKUP(P4,'MunicípiosEstados'!$K$2:$L$185,2,FALSE), O4="Distrito Federal",((W4*0.15)+(X4*0.7))*VLOOKUP(P4,'MunicípiosEstados'!$M$2:$N$2,2,FALSE), O4="Espírito Santo",((W4*0.15)+(X4*0.7))*VLOOKUP(P4,'MunicípiosEstados'!$O$2:$P$79,2,FALSE), O4="Goiás",((W4*0.15)+(X4*0.7))*VLOOKUP(P4,'MunicípiosEstados'!$Q$2:$R$247,2,FALSE), O4="Maranhão",((W4*0.15)+(X4*0.7))*VLOOKUP(P4,'MunicípiosEstados'!$S$2:$T$218,2,FALSE), O4="Mato Grosso",((W4*0.15)+(X4*0.7))*VLOOKUP(P4,'MunicípiosEstados'!$U$2:$V$143,2,FALSE), O4="Mato Grosso do Sul",((W4*0.15)+(X4*0.7))*VLOOKUP(P4,'MunicípiosEstados'!$W$2:$X$80,2,FALSE), O4="Minas Gerais",((W4*0.15)+(X4*0.7))*VLOOKUP(P4,'MunicípiosEstados'!$Y$2:$Z$854,2,FALSE), O4="Pará",((W4*0.15)+(X4*0.7))*VLOOKUP(P4,'MunicípiosEstados'!$AA$2:$AB$145,2,FALSE), O4="Paraíba",((W4*0.15)+(X4*0.7))*VLOOKUP(P4,'MunicípiosEstados'!$AC$2:$AD$224,2,FALSE), O4="Paraná",((W4*0.15)+(X4*0.7))*VLOOKUP(P4,'MunicípiosEstados'!$AE$2:$AF$400,2,FALSE), O4="Pernambuco",((W4*0.15)+(X4*0.7))*VLOOKUP(P4,'MunicípiosEstados'!$AG$2:$AH$186,2,FALSE), O4="Piauí",((W4*0.15)+(X4*0.7))*VLOOKUP(P4,'MunicípiosEstados'!$AI$2:$AJ$225,2,FALSE), O4="Rio Grande do Norte",((W4*0.15)+(X4*0.7))*VLOOKUP(P4,'MunicípiosEstados'!$AK$2:$AL$168,2,FALSE), O4="Rio Grande do Sul",((W4*0.15)+(X4*0.7))*VLOOKUP(P4,'MunicípiosEstados'!$AM$2:$AN$498,2,FALSE), O4="Rio de Janeiro",((W4*0.15)+(X4*0.7))*VLOOKUP(P4,'MunicípiosEstados'!$AO$2:$AP$93,2,FALSE), O4="Rondônia",((W4*0.15)+(X4*0.7))*VLOOKUP(P4,'MunicípiosEstados'!$AQ$2:$AR$53,2,FALSE), O4="Roraima",((W4*0.15)+(X4*0.7))*VLOOKUP(P4,'MunicípiosEstados'!$AS$2:$AT$16,2,FALSE), O4="Santa Catarina",((W4*0.15)+(X4*0.7))*VLOOKUP(P4,'MunicípiosEstados'!$AU$2:$AV$296,2,FALSE), O4="São Paulo",((W4*0.15)+(X4*0.7))*VLOOKUP(P4,'MunicípiosEstados'!$AW$2:$AX$646,2,FALSE), O4="Sergipe",((W4*0.15)+(X4*0.7))*VLOOKUP(P4,'MunicípiosEstados'!$AY$2:$AZ$76,2,FALSE), O4="Tocantins",((W4*0.15)+(X4*0.7))*VLOOKUP(P4,'MunicípiosEstados'!$BA$2:$BB$140,2,FALSE), O4="Exterior",((W4*0.15)+(X4*0.7))*VLOOKUP(P4,'MunicípiosEstados'!$BC$2:$BE$221,3,FALSE),TRUE,0 ) -> 2012.916 | AL4: =AK4+AJ4+AI4+AE4+AD4+AC4+AB4+AA4+Z4+Y4 -> 10012.916
A5: =ROW(A5)-1 -> 4 | B5: 45987.657 | C5: ronaldo@iapar.br | D5: Aprovado | E5: =VLOOKUP(G5,DiretoriaDepart.Coord.!$A$1:$C$72,2,FALSE) -> Pesquisa e Inovação | F5: =VLOOKUP(G5,DiretoriaDepart.Coord.!$A$1:$C$72,3,FALSE) -> Inovação e Comunicação Científica | G5: Fitotecnia e Fisiologia da Produção (Pesquisa) | I5: Capacitação em sistema Plantio Direto | J5: Encontro | K5: 3 | L5: Ronaldo Hissayuki Hojo Luiz Antonio Odenath Penha Ivan Bordin | M5: FEBRAPDP | N5: 300 | O5: Distrito Federal | P5: Brasília | Q5: 45845.333 | R5: 45847.708 | S5: Sim | T5: Presencial | U5: Produção Sustentavel | V5: Particpipação em evento com afinidade aos projetos de pesquisa em execução. | W5: 5 | X5: 5 | Y5: 500 | Z5: 1100 | AA5: 4000 | AB5: 0 | AC5: 300 | AD5: 0 | AE5: 0 | AF5: Não | AG5: 0 | AH5: Não | AI5: =IF(AF5="Sim",INT((R5-Q5+1))*K5*VLOOKUP(P5,'Tabelas Auxiliares'!$A$1:$C$400,3,FALSE),0) -> 0 | AJ5: =(AG5/10)*7 -> 0 | AK5: =IFS( O5="Acre",((W5*0.15)+(X5*0.7))*VLOOKUP(P5,'MunicípiosEstados'!$A$2:$B$23,2,FALSE), O5="Alagoas",((W5*0.15)+(X5*0.7))*VLOOKUP(P5,'MunicípiosEstados'!$C$2:$D$103,2,FALSE), O5="Amapá",((W5*0.15)+(X5*0.7))*VLOOKUP(P5,'MunicípiosEstados'!$E$2:$F$17,2,FALSE), O5="Amazonas",((W5*0.15)+(X5*0.7))*VLOOKUP(P5,'MunicípiosEstados'!$G$2:$H$63,2,FALSE), O5="Bahia",((W5*0.15)+(X5*0.7))*VLOOKUP(P5,'MunicípiosEstados'!$I$2:$J$418,2,FALSE), O5="Ceará",((W5*0.15)+(X5*0.7))*VLOOKUP(P5,'MunicípiosEstados'!$K$2:$L$185,2,FALSE), O5="Distrito Federal",((W5*0.15)+(X5*0.7))*VLOOKUP(P5,'MunicípiosEstados'!$M$2:$N$2,2,FALSE), O5="Espírito Santo",((W5*0.15)+(X5*0.7))*VLOOKUP(P5,'MunicípiosEstados'!$O$2:$P$79,2,FALSE), O5="Goiás",((W5*0.15)+(X5*0.7))*VLOOKUP(P5,'MunicípiosEstados'!$Q$2:$R$247,2,FALSE), O5="Maranhão",((W5*0.15)+(X5*0.7))*VLOOKUP(P5,'MunicípiosEstados'!$S$2:$T$218,2,FALSE), O5="Mato Grosso",((W5*0.15)+(X5*0.7))*VLOOKUP(P5,'MunicípiosEstados'!$U$2:$V$143,2,FALSE), O5="Mato Grosso do Sul",((W5*0.15)+(X5*0.7))*VLOOKUP(P5,'MunicípiosEstados'!$W$2:$X$80,2,FALSE), O5="Minas Gerais",((W5*0.15)+(X5*0.7))*VLOOKUP(P5,'MunicípiosEstados'!$Y$2:$Z$854,2,FALSE), O5="Pará",((W5*0.15)+(X5*0.7))*VLOOKUP(P5,'MunicípiosEstados'!$AA$2:$AB$145,2,FALSE), O5="Paraíba",((W5*0.15)+(X5*0.7))*VLOOKUP(P5,'MunicípiosEstados'!$AC$2:$AD$224,2,FALSE), O5="Paraná",((W5*0.15)+(X5*0.7))*VLOOKUP(P5,'MunicípiosEstados'!$AE$2:$AF$400,2,FALSE), O5="Pernambuco",((W5*0.15)+(X5*0.7))*VLOOKUP(P5,'MunicípiosEstados'!$AG$2:$AH$186,2,FALSE), O5="Piauí",((W5*0.15)+(X5*0.7))*VLOOKUP(P5,'MunicípiosEstados'!$AI$2:$AJ$225,2,FALSE), O5="Rio Grande do Norte",((W5*0.15)+(X5*0.7))*VLOOKUP(P5,'MunicípiosEstados'!$AK$2:$AL$168,2,FALSE), O5="Rio Grande do Sul",((W5*0.15)+(X5*0.7))*VLOOKUP(P5,'MunicípiosEstados'!$AM$2:$AN$498,2,FALSE), O5="Rio de Janeiro",((W5*0.15)+(X5*0.7))*VLOOKUP(P5,'MunicípiosEstados'!$AO$2:$AP$93,2,FALSE), O5="Rondônia",((W5*0.15)+(X5*0.7))*VLOOKUP(P5,'MunicípiosEstados'!$AQ$2:$AR$53,2,FALSE), O5="Roraima",((W5*0.15)+(X5*0.7))*VLOOKUP(P5,'MunicípiosEstados'!$AS$2:$AT$16,2,FALSE), O5="Santa Catarina",((W5*0.15)+(X5*0.7))*VLOOKUP(P5,'MunicípiosEstados'!$AU$2:$AV$296,2,FALSE), O5="São Paulo",((W5*0.15)+(X5*0.7))*VLOOKUP(P5,'MunicípiosEstados'!$AW$2:$AX$646,2,FALSE), O5="Sergipe",((W5*0.15)+(X5*0.7))*VLOOKUP(P5,'MunicípiosEstados'!$AY$2:$AZ$76,2,FALSE), O5="Tocantins",((W5*0.15)+(X5*0.7))*VLOOKUP(P5,'MunicípiosEstados'!$BA$2:$BB$140,2,FALSE), O5="Exterior",((W5*0.15)+(X5*0.7))*VLOOKUP(P5,'MunicípiosEstados'!$BC$2:$BE$221,3,FALSE),TRUE,0 ) -> 1989.51 | AL5: =AK5+AJ5+AI5+AE5+AD5+AC5+AB5+AA5+Z5+Y5 -> 7889.51 | AN5: Aprovado para dois participantes: Ronaldo Hojo e Ivan Bordin
A6: =ROW(A6)-1 -> 5 | B6: 45993.389 | C6: graziela_barbosa@idr.pr.gov.br | D6: Aprovado | E6: =VLOOKUP(G6,DiretoriaDepart.Coord.!$A$1:$C$72,2,FALSE) -> Pesquisa e Inovação | F6: =VLOOKUP(G6,DiretoriaDepart.Coord.!$A$1:$C$72,3,FALSE) -> Inovação e Comunicação Científica | G6: Solos e Meio Ambiente (Pesquisa) | I6: 20° Encontro Nacional do Sistema Plantio Direto e 3° Encontro Mundial do Sistema Plantio Direto | J6: Encontro | K6: 2 | L6: Graziela Moraes de Cesare Barbosa e Josiane Burkner dos Santos | M6: FEBRAPDP | N6: 0 | O6: Distrito Federal | P6: Brasília | Q6: 45845.333 | R6: 45847.708 | S6: Sim | T6: Presencial | U6: Discussões sobre plantio direto na palha | V6: Manter a visibilidade do IDR-Paraná como instituição que conduziu e conduz o Paraná como o estado com maior produtividade e sustentabilidade exatamente por essa instituição ter escolhido desde os anos 80 o fomento da prática do SPD, é muito importante para continuarmos sendo reconhecidos como uma empresa que gera pesquisa de qualidade para o mundo. | W6: 18 | X6: 8 | Y6: 1600 | Z6: 500 | AA6: 7500 | AB6: 0 | AC6: 2000 | AD6: 0 | AE6: 0 | AF6: Não | AG6: 0 | AH6: Não | AI6: =IF(AF6="Sim",INT((R6-Q6+1))*K6*VLOOKUP(P6,'Tabelas Auxiliares'!$A$1:$C$400,3,FALSE),0) -> 0 | AJ6: =(AG6/10)*7 -> 0 | AK6: =IFS( O6="Acre",((W6*0.15)+(X6*0.7))*VLOOKUP(P6,'MunicípiosEstados'!$A$2:$B$23,2,FALSE), O6="Alagoas",((W6*0.15)+(X6*0.7))*VLOOKUP(P6,'MunicípiosEstados'!$C$2:$D$103,2,FALSE), O6="Amapá",((W6*0.15)+(X6*0.7))*VLOOKUP(P6,'MunicípiosEstados'!$E$2:$F$17,2,FALSE), O6="Amazonas",((W6*0.15)+(X6*0.7))*VLOOKUP(P6,'MunicípiosEstados'!$G$2:$H$63,2,FALSE), O6="Bahia",((W6*0.15)+(X6*0.7))*VLOOKUP(P6,'MunicípiosEstados'!$I$2:$J$418,2,FALSE), O6="Ceará",((W6*0.15)+(X6*0.7))*VLOOKUP(P6,'MunicípiosEstados'!$K$2:$L$185,2,FALSE), O6="Distrito Federal",((W6*0.15)+(X6*0.7))*VLOOKUP(P6,'MunicípiosEstados'!$M$2:$N$2,2,FALSE), O6="Espírito Santo",((W6*0.15)+(X6*0.7))*VLOOKUP(P6,'MunicípiosEstados'!$O$2:$P$79,2,FALSE), O6="Goiás",((W6*0.15)+(X6*0.7))*VLOOKUP(P6,'MunicípiosEstados'!$Q$2:$R$247,2,FALSE), O6="Maranhão",((W6*0.15)+(X6*0.7))*VLOOKUP(P6,'MunicípiosEstados'!$S$2:$T$218,2,FALSE), O6="Mato Grosso",((W6*0.15)+(X6*0.7))*VLOOKUP(P6,'MunicípiosEstados'!$U$2:$V$143,2,FALSE), O6="Mato Grosso do Sul",((W6*0.15)+(X6*0.7))*VLOOKUP(P6,'MunicípiosEstados'!$W$2:$X$80,2,FALSE), O6="Minas Gerais",((W6*0.15)+(X6*0.7))*VLOOKUP(P6,'MunicípiosEstados'!$Y$2:$Z$854,2,FALSE), O6="Pará",((W6*0.15)+(X6*0.7))*VLOOKUP(P6,'MunicípiosEstados'!$AA$2:$AB$145,2,FALSE), O6="Paraíba",((W6*0.15)+(X6*0.7))*VLOOKUP(P6,'MunicípiosEstados'!$AC$2:$AD$224,2,FALSE), O6="Paraná",((W6*0.15)+(X6*0.7))*VLOOKUP(P6,'MunicípiosEstados'!$AE$2:$AF$400,2,FALSE), O6="Pernambuco",((W6*0.15)+(X6*0.7))*VLOOKUP(P6,'MunicípiosEstados'!$AG$2:$AH$186,2,FALSE), O6="Piauí",((W6*0.15)+(X6*0.7))*VLOOKUP(P6,'MunicípiosEstados'!$AI$2:$AJ$225,2,FALSE), O6="Rio Grande do Norte",((W6*0.15)+(X6*0.7))*VLOOKUP(P6,'MunicípiosEstados'!$AK$2:$AL$168,2,FALSE), O6="Rio Grande do Sul",((W6*0.15)+(X6*0.7))*VLOOKUP(P6,'MunicípiosEstados'!$AM$2:$AN$498,2,FALSE), O6="Rio de Janeiro",((W6*0.15)+(X6*0.7))*VLOOKUP(P6,'MunicípiosEstados'!$AO$2:$AP$93,2,FALSE), O6="Rondônia",((W6*0.15)+(X6*0.7))*VLOOKUP(P6,'MunicípiosEstados'!$AQ$2:$AR$53,2,FALSE), O6="Roraima",((W6*0.15)+(X6*0.7))*VLOOKUP(P6,'MunicípiosEstados'!$AS$2:$AT$16,2,FALSE), O6="Santa Catarina",((W6*0.15)+(X6*0.7))*VLOOKUP(P6,'MunicípiosEstados'!$AU$2:$AV$296,2,FALSE), O6="São Paulo",((W6*0.15)+(X6*0.7))*VLOOKUP(P6,'MunicípiosEstados'!$AW$2:$AX$646,2,FALSE), O6="Sergipe",((W6*0.15)+(X6*0.7))*VLOOKUP(P6,'MunicípiosEstados'!$AY$2:$AZ$76,2,FALSE), O6="Tocantins",((W6*0.15)+(X6*0.7))*VLOOKUP(P6,'MunicípiosEstados'!$BA$2:$BB$140,2,FALSE), O6="Exterior",((W6*0.15)+(X6*0.7))*VLOOKUP(P6,'MunicípiosEstados'!$BC$2:$BE$221,3,FALSE),TRUE,0 ) -> 3885.396 | AL6: =AK6+AJ6+AI6+AE6+AD6+AC6+AB6+AA6+Z6+Y6 -> 15485.396 | AN6: Aprovado para Graziela Barbosa e Josiane Burkner
A7: =ROW(A7)-1 -> 6 | B7: 45995.431 | C7: joaoreis@idr.pr.gov.br | D7: A aprovar | E7: =VLOOKUP(G7,DiretoriaDepart.Coord.!$A$1:$C$72,2,FALSE) -> Extensão Rural | F7: =VLOOKUP(G7,DiretoriaDepart.Coord.!$A$1:$C$72,3,FALSE) -> Projetos e Cadeias Produtivas | G7: Olericultura (Extensão Rural) | I7: 58º Congresso Brasileiro de Olericultura | J7: Congresso | K7: 10 | M7: ABH | N7: 500 | O7: Distrito Federal | P7: Brasília | Q7: 45859.333 | R7: 45862.708 | S7: Sim | T7: Presencial | U7: Desafios da Agricultura Familiar frente às Mudanças Climáticas | V7: As mudanças climáticas tem provocado grande impacto na produção de hortaliças no Brasil e principalmente no Paraná, dessa forma, participar desse debate permitirá aos nossos profissionais definir estratégia para conviver com essas mudanças permitindo manter a produção e produtividade das hortaliças. | W7: 110 | X7: 50 | Y7: 15000 | Z7: 0 | AA7: 30000 | AB7: 0 | AC7: 2000 | AD7: 0 | AE7: 0 | AF7: Não | AG7: 5000 | AH7: Não | AI7: =IF(AF7="Sim",INT((R7-Q7+1))*K7*VLOOKUP(P7,'Tabelas Auxiliares'!$A$1:$C$400,3,FALSE),0) -> 0 | AJ7: =(AG7/10)*7 -> 3500 | AK7: =IFS( O7="Acre",((W7*0.15)+(X7*0.7))*VLOOKUP(P7,'MunicípiosEstados'!$A$2:$B$23,2,FALSE), O7="Alagoas",((W7*0.15)+(X7*0.7))*VLOOKUP(P7,'MunicípiosEstados'!$C$2:$D$103,2,FALSE), O7="Amapá",((W7*0.15)+(X7*0.7))*VLOOKUP(P7,'MunicípiosEstados'!$E$2:$F$17,2,FALSE), O7="Amazonas",((W7*0.15)+(X7*0.7))*VLOOKUP(P7,'MunicípiosEstados'!$G$2:$H$63,2,FALSE), O7="Bahia",((W7*0.15)+(X7*0.7))*VLOOKUP(P7,'MunicípiosEstados'!$I$2:$J$418,2,FALSE), O7="Ceará",((W7*0.15)+(X7*0.7))*VLOOKUP(P7,'MunicípiosEstados'!$K$2:$L$185,2,FALSE), O7="Distrito Federal",((W7*0.15)+(X7*0.7))*VLOOKUP(P7,'MunicípiosEstados'!$M$2:$N$2,2,FALSE), O7="Espírito Santo",((W7*0.15)+(X7*0.7))*VLOOKUP(P7,'MunicípiosEstados'!$O$2:$P$79,2,FALSE), O7="Goiás",((W7*0.15)+(X7*0.7))*VLOOKUP(P7,'MunicípiosEstados'!$Q$2:$R$247,2,FALSE), O7="Maranhão",((W7*0.15)+(X7*0.7))*VLOOKUP(P7,'MunicípiosEstados'!$S$2:$T$218,2,FALSE), O7="Mato Grosso",((W7*0.15)+(X7*0.7))*VLOOKUP(P7,'MunicípiosEstados'!$U$2:$V$143,2,FALSE), O7="Mato Grosso do Sul",((W7*0.15)+(X7*0.7))*VLOOKUP(P7,'MunicípiosEstados'!$W$2:$X$80,2,FALSE), O7="Minas Gerais",((W7*0.15)+(X7*0.7))*VLOOKUP(P7,'MunicípiosEstados'!$Y$2:$Z$854,2,FALSE), O7="Pará",((W7*0.15)+(X7*0.7))*VLOOKUP(P7,'MunicípiosEstados'!$AA$2:$AB$145,2,FALSE), O7="Paraíba",((W7*0.15)+(X7*0.7))*VLOOKUP(P7,'MunicípiosEstados'!$AC$2:$AD$224,2,FALSE), O7="Paraná",((W7*0.15)+(X7*0.7))*VLOOKUP(P7,'MunicípiosEstados'!$AE$2:$AF$400,2,FALSE), O7="Pernambuco",((W7*0.15)+(X7*0.7))*VLOOKUP(P7,'MunicípiosEstados'!$AG$2:$AH$186,2,FALSE), O7="Piauí",((W7*0.15)+(X7*0.7))*VLOOKUP(P7,'MunicípiosEstados'!$AI$2:$AJ$225,2,FALSE), O7="Rio Grande do Norte",((W7*0.15)+(X7*0.7))*VLOOKUP(P7,'MunicípiosEstados'!$AK$2:$AL$168,2,FALSE), O7="Rio Grande do Sul",((W7*0.15)+(X7*0.7))*VLOOKUP(P7,'MunicípiosEstados'!$AM$2:$AN$498,2,FALSE), O7="Rio de Janeiro",((W7*0.15)+(X7*0.7))*VLOOKUP(P7,'MunicípiosEstados'!$AO$2:$AP$93,2,FALSE), O7="Rondônia",((W7*0.15)+(X7*0.7))*VLOOKUP(P7,'MunicípiosEstados'!$AQ$2:$AR$53,2,FALSE), O7="Roraima",((W7*0.15)+(X7*0.7))*VLOOKUP(P7,'MunicípiosEstados'!$AS$2:$AT$16,2,FALSE), O7="Santa Catarina",((W7*0.15)+(X7*0.7))*VLOOKUP(P7,'MunicípiosEstados'!$AU$2:$AV$296,2,FALSE), O7="São Paulo",((W7*0.15)+(X7*0.7))*VLOOKUP(P7,'MunicípiosEstados'!$AW$2:$AX$646,2,FALSE), O7="Sergipe",((W7*0.15)+(X7*0.7))*VLOOKUP(P7,'MunicípiosEstados'!$AY$2:$AZ$76,2,FALSE), O7="Tocantins",((W7*0.15)+(X7*0.7))*VLOOKUP(P7,'MunicípiosEstados'!$BA$2:$BB$140,2,FALSE), O7="Exterior",((W7*0.15)+(X7*0.7))*VLOOKUP(P7,'MunicípiosEstados'!$BC$2:$BE$221,3,FALSE),TRUE,0 ) -> 24108.18 | AL7: =AK7+AJ7+AI7+AE7+AD7+AC7+AB7+AA7+Z7+Y7 -> 74608.18
A8: =ROW(A8)-1 -> 7 | B8: 45996.65 | C8: joiceassmann@idr.pr.gov.br | D8: A aprovar | E8: =VLOOKUP(G8,DiretoriaDepart.Coord.!$A$1:$C$72,2,FALSE) -> Pesquisa e Inovação | F8: =VLOOKUP(G8,DiretoriaDepart.Coord.!$A$1:$C$72,3,FALSE) -> Inovação e Comunicação Científica | G8: Polo de Pesquisa de Pato Branco | I8: 20° Encontro Nacional do Sistema Plantio Direto e 3° Encontro Mundial do Sistema Plantio Direto | J8: Encontro | K8: 5 | L8: Joice Mari Assmann | M8: FEBRAPDP e ENSPD | N8: 1000 | O8: Distrito Federal | P8: Brasília | Q8: 45845.333 | R8: 45847.708 | S8: Sim | T8: Presencial | U8: "Sistema Plantio Direto: base para a Agricultura Regenerativa" | V8: O Paraná consolidou-se como o berço do Plantio Direto, sendo referência mundial nesse sistema de cultivo. O IDR-Paraná, pioneiro e protagonista nos estudos e avanços relacionados aos seus pilares, rotação de culturas, uso de plantas de cobertura e manejo sustentável do solo, desempenhou papel fundamental na construção desse legado. Diante dessa trajetória, é imprescindível que a instituição esteja representada em âmbito nacional e internacional, fortalecendo sua posição de liderança e credibilidade. Participar desses espaços nos permite não apenas aprimorar conhecimentos e incorporar inovações, mas também compartilhar resultados e experiências que contribuem para o desenvolvimento da agricultura sustentável no Brasil e no mundo. | W8: 8 | X8: 4 | Y8: 800 | Z8: 150 | AA8: 3000 | AB8: 400 | AC8: 200 | AD8: 0 | AE8: 0 | AF8: Não | AG8: 0 | AH8: Sim | AI8: =IF(AF8="Sim",INT((R8-Q8+1))*K8*VLOOKUP(P8,'Tabelas Auxiliares'!$A$1:$C$400,3,FALSE),0) -> 0 | AJ8: =(AG8/10)*7 -> 0 | AK8: =IFS( O8="Acre",((W8*0.15)+(X8*0.7))*VLOOKUP(P8,'MunicípiosEstados'!$A$2:$B$23,2,FALSE), O8="Alagoas",((W8*0.15)+(X8*0.7))*VLOOKUP(P8,'MunicípiosEstados'!$C$2:$D$103,2,FALSE), O8="Amapá",((W8*0.15)+(X8*0.7))*VLOOKUP(P8,'MunicípiosEstados'!$E$2:$F$17,2,FALSE), O8="Amazonas",((W8*0.15)+(X8*0.7))*VLOOKUP(P8,'MunicípiosEstados'!$G$2:$H$63,2,FALSE), O8="Bahia",((W8*0.15)+(X8*0.7))*VLOOKUP(P8,'MunicípiosEstados'!$I$2:$J$418,2,FALSE), O8="Ceará",((W8*0.15)+(X8*0.7))*VLOOKUP(P8,'MunicípiosEstados'!$K$2:$L$185,2,FALSE), O8="Distrito Federal",((W8*0.15)+(X8*0.7))*VLOOKUP(P8,'MunicípiosEstados'!$M$2:$N$2,2,FALSE), O8="Espírito Santo",((W8*0.15)+(X8*0.7))*VLOOKUP(P8,'MunicípiosEstados'!$O$2:$P$79,2,FALSE), O8="Goiás",((W8*0.15)+(X8*0.7))*VLOOKUP(P8,'MunicípiosEstados'!$Q$2:$R$247,2,FALSE), O8="Maranhão",((W8*0.15)+(X8*0.7))*VLOOKUP(P8,'MunicípiosEstados'!$S$2:$T$218,2,FALSE), O8="Mato Grosso",((W8*0.15)+(X8*0.7))*VLOOKUP(P8,'MunicípiosEstados'!$U$2:$V$143,2,FALSE), O8="Mato Grosso do Sul",((W8*0.15)+(X8*0.7))*VLOOKUP(P8,'MunicípiosEstados'!$W$2:$X$80,2,FALSE), O8="Minas Gerais",((W8*0.15)+(X8*0.7))*VLOOKUP(P8,'MunicípiosEstados'!$Y$2:$Z$854,2,FALSE), O8="Pará",((W8*0.15)+(X8*0.7))*VLOOKUP(P8,'MunicípiosEstados'!$AA$2:$AB$145,2,FALSE), O8="Paraíba",((W8*0.15)+(X8*0.7))*VLOOKUP(P8,'MunicípiosEstados'!$AC$2:$AD$224,2,FALSE), O8="Paraná",((W8*0.15)+(X8*0.7))*VLOOKUP(P8,'MunicípiosEstados'!$AE$2:$AF$400,2,FALSE), O8="Pernambuco",((W8*0.15)+(X8*0.7))*VLOOKUP(P8,'MunicípiosEstados'!$AG$2:$AH$186,2,FALSE), O8="Piauí",((W8*0.15)+(X8*0.7))*VLOOKUP(P8,'MunicípiosEstados'!$AI$2:$AJ$225,2,FALSE), O8="Rio Grande do Norte",((W8*0.15)+(X8*0.7))*VLOOKUP(P8,'MunicípiosEstados'!$AK$2:$AL$168,2,FALSE), O8="Rio Grande do Sul",((W8*0.15)+(X8*0.7))*VLOOKUP(P8,'MunicípiosEstados'!$AM$2:$AN$498,2,FALSE), O8="Rio de Janeiro",((W8*0.15)+(X8*0.7))*VLOOKUP(P8,'MunicípiosEstados'!$AO$2:$AP$93,2,FALSE), O8="Rondônia",((W8*0.15)+(X8*0.7))*VLOOKUP(P8,'MunicípiosEstados'!$AQ$2:$AR$53,2,FALSE), O8="Roraima",((W8*0.15)+(X8*0.7))*VLOOKUP(P8,'MunicípiosEstados'!$AS$2:$AT$16,2,FALSE), O8="Santa Catarina",((W8*0.15)+(X8*0.7))*VLOOKUP(P8,'MunicípiosEstados'!$AU$2:$AV$296,2,FALSE), O8="São Paulo",((W8*0.15)+(X8*0.7))*VLOOKUP(P8,'MunicípiosEstados'!$AW$2:$AX$646,2,FALSE), O8="Sergipe",((W8*0.15)+(X8*0.7))*VLOOKUP(P8,'MunicípiosEstados'!$AY$2:$AZ$76,2,FALSE), O8="Tocantins",((W8*0.15)+(X8*0.7))*VLOOKUP(P8,'MunicípiosEstados'!$BA$2:$BB$140,2,FALSE), O8="Exterior",((W8*0.15)+(X8*0.7))*VLOOKUP(P8,'MunicípiosEstados'!$BC$2:$BE$221,3,FALSE),TRUE,0 ) -> 1872.48 | AL8: =AK8+AJ8+AI8+AE8+AD8+AC8+AB8+AA8+Z8+Y8 -> 6422.48
A9: =ROW(A9)-1 -> 8 | B9: 45999.45 | C9: ivanbordin@idr.pr.gov.br | D9: A aprovar | E9: =VLOOKUP(G9,DiretoriaDepart.Coord.!$A$1:$C$72,2,FALSE) -> Pesquisa e Inovação | F9: =VLOOKUP(G9,DiretoriaDepart.Coord.!$A$1:$C$72,3,FALSE) -> Pesquisa e Capacitação | G9: Polo de Pesquisa de Londrina | I9: 20º Encontro Nacional do Sistema Plantio Direto e o 3º Encontro Mundial | J9: Congresso | K9: 1 | L9: Ivan Bordin | M9: Federação Brasileira de Plantio Direto na Palha | N9: 500 | O9: Distrito Federal | P9: Brasília | Q9: 45815.333 | R9: 45817.708 | S9: Sim | T9: Presencial | U9: Sistema Plantio Direto | V9: Sou Assessor do programa grãos: soja e milho. Sou gerente do projeto de produção sustentável de grãos em rotação de culturas, em parceria com a ITAIPÚ (AISA). Pretendo levar resumos científicos para o evento. | W9: 10 | X9: 5 | Y9: 1200 | Z9: 0 | AA9: 4000 | AB9: 0 | AC9: 400 | AD9: 0 | AE9: 0 | AF9: Não | AG9: 0 | AH9: Sim | AI9: =IF(AF9="Sim",INT((R9-Q9+1))*K9*VLOOKUP(P9,'Tabelas Auxiliares'!$A$1:$C$400,3,FALSE),0) -> 0 | AJ9: =(AG9/10)*7 -> 0 | AK9: =IFS( O9="Acre",((W9*0.15)+(X9*0.7))*VLOOKUP(P9,'MunicípiosEstados'!$A$2:$B$23,2,FALSE), O9="Alagoas",((W9*0.15)+(X9*0.7))*VLOOKUP(P9,'MunicípiosEstados'!$C$2:$D$103,2,FALSE), O9="Amapá",((W9*0.15)+(X9*0.7))*VLOOKUP(P9,'MunicípiosEstados'!$E$2:$F$17,2,FALSE), O9="Amazonas",((W9*0.15)+(X9*0.7))*VLOOKUP(P9,'MunicípiosEstados'!$G$2:$H$63,2,FALSE), O9="Bahia",((W9*0.15)+(X9*0.7))*VLOOKUP(P9,'MunicípiosEstados'!$I$2:$J$418,2,FALSE), O9="Ceará",((W9*0.15)+(X9*0.7))*VLOOKUP(P9,'MunicípiosEstados'!$K$2:$L$185,2,FALSE), O9="Distrito Federal",((W9*0.15)+(X9*0.7))*VLOOKUP(P9,'MunicípiosEstados'!$M$2:$N$2,2,FALSE), O9="Espírito Santo",((W9*0.15)+(X9*0.7))*VLOOKUP(P9,'MunicípiosEstados'!$O$2:$P$79,2,FALSE), O9="Goiás",((W9*0.15)+(X9*0.7))*VLOOKUP(P9,'MunicípiosEstados'!$Q$2:$R$247,2,FALSE), O9="Maranhão",((W9*0.15)+(X9*0.7))*VLOOKUP(P9,'MunicípiosEstados'!$S$2:$T$218,2,FALSE), O9="Mato Grosso",((W9*0.15)+(X9*0.7))*VLOOKUP(P9,'MunicípiosEstados'!$U$2:$V$143,2,FALSE), O9="Mato Grosso do Sul",((W9*0.15)+(X9*0.7))*VLOOKUP(P9,'MunicípiosEstados'!$W$2:$X$80,2,FALSE), O9="Minas Gerais",((W9*0.15)+(X9*0.7))*VLOOKUP(P9,'MunicípiosEstados'!$Y$2:$Z$854,2,FALSE), O9="Pará",((W9*0.15)+(X9*0.7))*VLOOKUP(P9,'MunicípiosEstados'!$AA$2:$AB$145,2,FALSE), O9="Paraíba",((W9*0.15)+(X9*0.7))*VLOOKUP(P9,'MunicípiosEstados'!$AC$2:$AD$224,2,FALSE), O9="Paraná",((W9*0.15)+(X9*0.7))*VLOOKUP(P9,'MunicípiosEstados'!$AE$2:$AF$400,2,FALSE), O9="Pernambuco",((W9*0.15)+(X9*0.7))*VLOOKUP(P9,'MunicípiosEstados'!$AG$2:$AH$186,2,FALSE), O9="Piauí",((W9*0.15)+(X9*0.7))*VLOOKUP(P9,'MunicípiosEstados'!$AI$2:$AJ$225,2,FALSE), O9="Rio Grande do Norte",((W9*0.15)+(X9*0.7))*VLOOKUP(P9,'MunicípiosEstados'!$AK$2:$AL$168,2,FALSE), O9="Rio Grande do Sul",((W9*0.15)+(X9*0.7))*VLOOKUP(P9,'MunicípiosEstados'!$AM$2:$AN$498,2,FALSE), O9="Rio de Janeiro",((W9*0.15)+(X9*0.7))*VLOOKUP(P9,'MunicípiosEstados'!$AO$2:$AP$93,2,FALSE), O9="Rondônia",((W9*0.15)+(X9*0.7))*VLOOKUP(P9,'MunicípiosEstados'!$AQ$2:$AR$53,2,FALSE), O9="Roraima",((W9*0.15)+(X9*0.7))*VLOOKUP(P9,'MunicípiosEstados'!$AS$2:$AT$16,2,FALSE), O9="Santa Catarina",((W9*0.15)+(X9*0.7))*VLOOKUP(P9,'MunicípiosEstados'!$AU$2:$AV$296,2,FALSE), O9="São Paulo",((W9*0.15)+(X9*0.7))*VLOOKUP(P9,'MunicípiosEstados'!$AW$2:$AX$646,2,FALSE), O9="Sergipe",((W9*0.15)+(X9*0.7))*VLOOKUP(P9,'MunicípiosEstados'!$AY$2:$AZ$76,2,FALSE), O9="Tocantins",((W9*0.15)+(X9*0.7))*VLOOKUP(P9,'MunicípiosEstados'!$BA$2:$BB$140,2,FALSE), O9="Exterior",((W9*0.15)+(X9*0.7))*VLOOKUP(P9,'MunicípiosEstados'!$BC$2:$BE$221,3,FALSE),TRUE,0 ) -> 2340.6 | AL9: =AK9+AJ9+AI9+AE9+AD9+AC9+AB9+AA9+Z9+Y9 -> 7940.6
A10: =ROW(A10)-1 -> 9 | B10: 45999.629 | C10: patriciasantoro@idr.pr.gov.br | D10: Não Aprovado | E10: =VLOOKUP(G10,DiretoriaDepart.Coord.!$A$1:$C$72,2,FALSE) -> Pesquisa e Inovação | F10: =VLOOKUP(G10,DiretoriaDepart.Coord.!$A$1:$C$72,3,FALSE) -> Inovação e Comunicação Científica | G10: Fitotecnia e Fisiologia da Produção (Pesquisa) | I10: 20° Encontro Nacional do Sistema Plantio Direto e 3° Encontro Mundial do Sistema Plantio Direto | J10: Encontro | K10: 1 | L10: 1 | M10: não há | N10: 0 | O10: Distrito Federal | P10: Brasília | Q10: 45845.333 | R10: 45847.708 | S10: Não | T10: Presencial | U10: O encontro reunirá produtores, pesquisadores e lideranças do setor e simboliza um dos principais fóruns do agronegócio para discussão de técnicas de agricultura sustentável. | V10: Considerando que o Paraná foi o "berço" do Plantio Direto e que o IDR-Paraná foi pioneiro e extremamente relevante nos estudos e avanços relacionados aos pilares deste sistema de cultivo (rotação de culturas, plantas de cobertura e manejo do solo) é de suma importância representarmos a instituição em nivel nacional e mundial, inclusive salientar que em 2026 o projeto de pesquisa mais antigo de Plantio Direto da instituição conduzido em Pato Branco completa 40 anos! | W10: 8 | X10: 5 | Y10: 500 | Z10: 100 | AA10: 2500 | AB10: 0 | AC10: 300 | AD10: 0 | AE10: 0 | AF10: Não | AG10: 0 | AH10: Não | AI10: =IF(AF10="Sim",INT((R10-Q10+1))*K10*VLOOKUP(P10,'Tabelas Auxiliares'!$A$1:$C$400,3,FALSE),0) -> 0 | AJ10: =(AG10/10)*7 -> 0 | AK10: =IFS( O10="Acre",((W10*0.15)+(X10*0.7))*VLOOKUP(P10,'MunicípiosEstados'!$A$2:$B$23,2,FALSE), O10="Alagoas",((W10*0.15)+(X10*0.7))*VLOOKUP(P10,'MunicípiosEstados'!$C$2:$D$103,2,FALSE), O10="Amapá",((W10*0.15)+(X10*0.7))*VLOOKUP(P10,'MunicípiosEstados'!$E$2:$F$17,2,FALSE), O10="Amazonas",((W10*0.15)+(X10*0.7))*VLOOKUP(P10,'MunicípiosEstados'!$G$2:$H$63,2,FALSE), O10="Bahia",((W10*0.15)+(X10*0.7))*VLOOKUP(P10,'MunicípiosEstados'!$I$2:$J$418,2,FALSE), O10="Ceará",((W10*0.15)+(X10*0.7))*VLOOKUP(P10,'MunicípiosEstados'!$K$2:$L$185,2,FALSE), O10="Distrito Federal",((W10*0.15)+(X10*0.7))*VLOOKUP(P10,'MunicípiosEstados'!$M$2:$N$2,2,FALSE), O10="Espírito Santo",((W10*0.15)+(X10*0.7))*VLOOKUP(P10,'MunicípiosEstados'!$O$2:$P$79,2,FALSE), O10="Goiás",((W10*0.15)+(X10*0.7))*VLOOKUP(P10,'MunicípiosEstados'!$Q$2:$R$247,2,FALSE), O10="Maranhão",((W10*0.15)+(X10*0.7))*VLOOKUP(P10,'MunicípiosEstados'!$S$2:$T$218,2,FALSE), O10="Mato Grosso",((W10*0.15)+(X10*0.7))*VLOOKUP(P10,'MunicípiosEstados'!$U$2:$V$143,2,FALSE), O10="Mato Grosso do Sul",((W10*0.15)+(X10*0.7))*VLOOKUP(P10,'MunicípiosEstados'!$W$2:$X$80,2,FALSE), O10="Minas Gerais",((W10*0.15)+(X10*0.7))*VLOOKUP(P10,'MunicípiosEstados'!$Y$2:$Z$854,2,FALSE), O10="Pará",((W10*0.15)+(X10*0.7))*VLOOKUP(P10,'MunicípiosEstados'!$AA$2:$AB$145,2,FALSE), O10="Paraíba",((W10*0.15)+(X10*0.7))*VLOOKUP(P10,'MunicípiosEstados'!$AC$2:$AD$224,2,FALSE), O10="Paraná",((W10*0.15)+(X10*0.7))*VLOOKUP(P10,'MunicípiosEstados'!$AE$2:$AF$400,2,FALSE), O10="Pernambuco",((W10*0.15)+(X10*0.7))*VLOOKUP(P10,'MunicípiosEstados'!$AG$2:$AH$186,2,FALSE), O10="Piauí",((W10*0.15)+(X10*0.7))*VLOOKUP(P10,'MunicípiosEstados'!$AI$2:$AJ$225,2,FALSE), O10="Rio Grande do Norte",((W10*0.15)+(X10*0.7))*VLOOKUP(P10,'MunicípiosEstados'!$AK$2:$AL$168,2,FALSE), O10="Rio Grande do Sul",((W10*0.15)+(X10*0.7))*VLOOKUP(P10,'MunicípiosEstados'!$AM$2:$AN$498,2,FALSE), O10="Rio de Janeiro",((W10*0.15)+(X10*0.7))*VLOOKUP(P10,'MunicípiosEstados'!$AO$2:$AP$93,2,FALSE), O10="Rondônia",((W10*0.15)+(X10*0.7))*VLOOKUP(P10,'MunicípiosEstados'!$AQ$2:$AR$53,2,FALSE), O10="Roraima",((W10*0.15)+(X10*0.7))*VLOOKUP(P10,'MunicípiosEstados'!$AS$2:$AT$16,2,FALSE), O10="Santa Catarina",((W10*0.15)+(X10*0.7))*VLOOKUP(P10,'MunicípiosEstados'!$AU$2:$AV$296,2,FALSE), O10="São Paulo",((W10*0.15)+(X10*0.7))*VLOOKUP(P10,'MunicípiosEstados'!$AW$2:$AX$646,2,FALSE), O10="Sergipe",((W10*0.15)+(X10*0.7))*VLOOKUP(P10,'MunicípiosEstados'!$AY$2:$AZ$76,2,FALSE), O10="Tocantins",((W10*0.15)+(X10*0.7))*VLOOKUP(P10,'MunicípiosEstados'!$BA$2:$BB$140,2,FALSE), O10="Exterior",((W10*0.15)+(X10*0.7))*VLOOKUP(P10,'MunicípiosEstados'!$BC$2:$BE$221,3,FALSE),TRUE,0 ) -> 2200.164 | AL10: =AK10+AJ10+AI10+AE10+AD10+AC10+AB10+AA10+Z10+Y10 -> 5600.164 | AN10: Não aprovado por falta de informações: Nome do participante
A11: =ROW(A11)-1 -> 10 | B11: 45999.785 | C11: sramos@idr.pr.gov.br | D11: A aprovar | E11: =VLOOKUP(G11,DiretoriaDepart.Coord.!$A$1:$C$72,2,FALSE) -> Extensão Rural | F11: =VLOOKUP(G11,DiretoriaDepart.Coord.!$A$1:$C$72,3,FALSE) -> Políticas Públicas | G11: Turismo Rural (Extensão Rural) | I11: MISSÃO TÉCNICA COM O SEBRAE | J11: Excursão | K11: 5 | L11: Sidney Aurelio Valeriano Ramos, Ailton Rojas Poppi, Delma Fabiola Ferreira da Silva, Rogerio da Silva Almeida e Varlei Toller | M11: SEBRAE | N11: 30 | O11: Espírito Santo | P11: Venda Nova do Imigrante | Q11: 45719.333 | R11: 45721.708 | S11: Não | T11: Presencial | U11: TURISMO RURAL | V11: A realização da missão técnica entre o Instituto de Desenvolvimento Rural do Paraná (IDR-Paraná) e o Serviço Brasileiro de Apoio às Micro e Pequenas Empresas (SEBRAE) justifica-se como ação estratégica decorrente do acordo de cooperação vigente entre os dois entes, cujo objetivo é promover o desenvolvimento sustentável, a inovação e a competitividade dos empreendimentos rurais no Estado do Paraná. O acordo de cooperação estabelece a integração de esforços para fortalecimento das cadeias produtivas, difusão de tecnologias, aprimoramento de metodologias de assistência técnica e extensão rural (ATER), além da qualificação de produtores, técnicos e gestores. Nesse contexto, a missão técnica constitui etapa fundamental para o alinhamento de práticas, troca de experiências e identificação de soluções que contribuam para a melhoria contínua dos programas e projetos conjuntos. | W11: 45 | X11: 15 | Y11: 1500 | Z11: 0 | AA11: 7000 | AB11: 0 | AC11: 800 | AD11: 0 | AE11: 0 | AF11: Não | AG11: 1200 | AH11: Não | AI11: =IF(AF11="Sim",INT((R11-Q11+1))*K11*VLOOKUP(P11,'Tabelas Auxiliares'!$A$1:$C$400,3,FALSE),0) -> 0 | AJ11: =(AG11/10)*7 -> 840 | AK11: =IFS( O11="Acre",((W11*0.15)+(X11*0.7))*VLOOKUP(P11,'MunicípiosEstados'!$A$2:$B$23,2,FALSE), O11="Alagoas",((W11*0.15)+(X11*0.7))*VLOOKUP(P11,'MunicípiosEstados'!$C$2:$D$103,2,FALSE), O11="Amapá",((W11*0.15)+(X11*0.7))*VLOOKUP(P11,'MunicípiosEstados'!$E$2:$F$17,2,FALSE), O11="Amazonas",((W11*0.15)+(X11*0.7))*VLOOKUP(P11,'MunicípiosEstados'!$G$2:$H$63,2,FALSE), O11="Bahia",((W11*0.15)+(X11*0.7))*VLOOKUP(P11,'MunicípiosEstados'!$I$2:$J$418,2,FALSE), O11="Ceará",((W11*0.15)+(X11*0.7))*VLOOKUP(P11,'MunicípiosEstados'!$K$2:$L$185,2,FALSE), O11="Distrito Federal",((W11*0.15)+(X11*0.7))*VLOOKUP(P11,'MunicípiosEstados'!$M$2:$N$2,2,FALSE), O11="Espírito Santo",((W11*0.15)+(X11*0.7))*VLOOKUP(P11,'MunicípiosEstados'!$O$2:$P$79,2,FALSE), O11="Goiás",((W11*0.15)+(X11*0.7))*VLOOKUP(P11,'MunicípiosEstados'!$Q$2:$R$247,2,FALSE), O11="Maranhão",((W11*0.15)+(X11*0.7))*VLOOKUP(P11,'MunicípiosEstados'!$S$2:$T$218,2,FALSE), O11="Mato Grosso",((W11*0.15)+(X11*0.7))*VLOOKUP(P11,'MunicípiosEstados'!$U$2:$V$143,2,FALSE), O11="Mato Grosso do Sul",((W11*0.15)+(X11*0.7))*VLOOKUP(P11,'MunicípiosEstados'!$W$2:$X$80,2,FALSE), O11="Minas Gerais",((W11*0.15)+(X11*0.7))*VLOOKUP(P11,'MunicípiosEstados'!$Y$2:$Z$854,2,FALSE), O11="Pará",((W11*0.15)+(X11*0.7))*VLOOKUP(P11,'MunicípiosEstados'!$AA$2:$AB$145,2,FALSE), O11="Paraíba",((W11*0.15)+(X11*0.7))*VLOOKUP(P11,'MunicípiosEstados'!$AC$2:$AD$224,2,FALSE), O11="Paraná",((W11*0.15)+(X11*0.7))*VLOOKUP(P11,'MunicípiosEstados'!$AE$2:$AF$400,2,FALSE), O11="Pernambuco",((W11*0.15)+(X11*0.7))*VLOOKUP(P11,'MunicípiosEstados'!$AG$2:$AH$186,2,FALSE), O11="Piauí",((W11*0.15)+(X11*0.7))*VLOOKUP(P11,'MunicípiosEstados'!$AI$2:$AJ$225,2,FALSE), O11="Rio Grande do Norte",((W11*0.15)+(X11*0.7))*VLOOKUP(P11,'MunicípiosEstados'!$AK$2:$AL$168,2,FALSE), O11="Rio Grande do Sul",((W11*0.15)+(X11*0.7))*VLOOKUP(P11,'MunicípiosEstados'!$AM$2:$AN$498,2,FALSE), O11="Rio de Janeiro",((W11*0.15)+(X11*0.7))*VLOOKUP(P11,'MunicípiosEstados'!$AO$2:$AP$93,2,FALSE), O11="Rondônia",((W11*0.15)+(X11*0.7))*VLOOKUP(P11,'MunicípiosEstados'!$AQ$2:$AR$53,2,FALSE), O11="Roraima",((W11*0.15)+(X11*0.7))*VLOOKUP(P11,'MunicípiosEstados'!$AS$2:$AT$16,2,FALSE), O11="Santa Catarina",((W11*0.15)+(X11*0.7))*VLOOKUP(P11,'MunicípiosEstados'!$AU$2:$AV$296,2,FALSE), O11="São Paulo",((W11*0.15)+(X11*0.7))*VLOOKUP(P11,'MunicípiosEstados'!$AW$2:$AX$646,2,FALSE), O11="Sergipe",((W11*0.15)+(X11*0.7))*VLOOKUP(P11,'MunicípiosEstados'!$AY$2:$AZ$76,2,FALSE), O11="Tocantins",((W11*0.15)+(X11*0.7))*VLOOKUP(P11,'MunicípiosEstados'!$BA$2:$BB$140,2,FALSE), O11="Exterior",((W11*0.15)+(X11*0.7))*VLOOKUP(P11,'MunicípiosEstados'!$BC$2:$BE$221,3,FALSE),TRUE,0 ) -> 5011.9875 | AL11: =AK11+AJ11+AI11+AE11+AD11+AC11+AB11+AA11+Z11+Y11 -> 15151.987
A12: =ROW(A12)-1 -> 11 | B12: 45978.623 | C12: laisepontes@idr.pr.gov.br | D12: A aprovar | E12: =VLOOKUP(G12,DiretoriaDepart.Coord.!$A$1:$C$72,2,FALSE) -> Pesquisa e Inovação | F12: =VLOOKUP(G12,DiretoriaDepart.Coord.!$A$1:$C$72,3,FALSE) -> Pesquisa e Capacitação | G12: Programa de Pecuária de Corte e ILPF (Pesquisa) | I12: EGF 2026 | J12: Congresso | K12: 1 | L12: Laíse da Silveira Pontes | M12: European Grassland Federation | N12: 350 | O12: Exterior | P12: Portugal | Q12: 45759.333 | R12: 45763.75 | S12: Sim | T12: Presencial | U12: Desafios e inovações para a resiliência das pastagens. | V12: O congresso internacional do EGF “Desafios e inovações para a resiliência das pastagens” reunirá pesquisadores de diversos países que atuam na temática da sustentabilidade e resiliência dos sistemas de pastagens, constituindo-se em um espaço privilegiado para trocas de experiências, aprendizado e atualização científica. A participação de pesquisadores do IDR-Paraná em evento desta magnitude é de suma importância, considerando que os desafios enfrentados pelos sistemas de pastagens — como mudanças climáticas, abandono/degradação de áreas rurais, conflitos de uso da terra, riscos crescentes de incêndios, perda de biodiversidade, pressões sobre solo e água, além de transformações na demanda por proteína e nos sistemas de produção animal — também se refletem diretamente na realidade brasileira. Mudanças climáticas e pastagens, manejo do solo e da água • Impactos das mudanças climáticas sobre as pastagens • Capacidade das pastagens de se adaptar às mudanças climáticas • Sequestro de carbono em pastagens para mitigar as mudanças climáticas • Solo, água, práticas de cultivo e manejo do pastoreio para a estabilidade das pastagens • Novas tecnologias para o desenvolvimento e resiliência das pastagens Agroflorestas, pastoralismo e sociedade • O papel das pastagens na sustentabilidade das propriedades agroflorestais • Sinergias entre pastagens, arbustos, árvores e animais em sistemas agroflorestais • Práticas para prevenir a degradação em sistemas agroflorestais • Pastoreio e pastoralismo: atendendo às demandas da sociedade • O papel contemporâneo do pastoralismo • Pastoralismo e tecnologias emergentes • Pastoralismo: equilibrando o bem-estar dos agricultores, expectativas dos consumidores, bem-estar animal e biodiversidade Melhoramento para novos desafios • Incorporação de novas espécies vegetais nos sistemas agrícolas • Estratégias de melhoramento vegetal em resposta às mudanças nos padrões climáticos • Estratégias de melhoramento vegetal para reduzir emissões de metano • Características genéticas das plantas e seu papel na redução das emissões do pastoreio • Aproveitamento da diversidade genética animal para enfrentar novos desafios das pastagens Sistemas sustentáveis de produção pecuária baseados em pastagens: desafios e oportunidades • Manejo adaptado ao local baseado em pastagens • Serviços ecossistêmicos proporcionados pelo uso das pastagens pelo gado • Autossuficiência proteica de sistemas de produção de ruminantes e monogástricos • Pecuária de precisão • Qualidade e rotulagem de produtos animais baseados em pastagens Pastagens e ferramentas de políticas rurais para enfrentar desafios globais • Ferramentas de políticas para adaptação das funções das pastagens • Eco-esquemas e programas de desenvolvimento rural em resposta à perda de pastagens • Enfrentando desafios emergentes por meio de políticas públicas voltadas às pastagens • Construindo resiliência: políticas como proteção diante de crises futuras • Fomentando o papel das pastagens na estabilidade dos sistemas agrícolas A participação neste evento permitirá não apenas a atualização científica, mas também a apresentação de resultados de pesquisas já desenvolvidas no âmbito do IDR-Paraná, cujos trabalhos (2) foram aceitos pela organização do congresso para publicação nos General Meeting Proceedings. Trata-se, portanto, de uma oportunidade estratégica para dar visibilidade internacional às pesquisas realizadas, fortalecer parcerias e trazer subsídios técnicos e científicos que poderão ser aplicados em programas de extensão e políticas públicas voltadas ao setor agropecuário paranaense. A presença neste evento internacional contribuirá significativamente para o fortalecimento da atuação do IDR-Paraná na temática das pastagens e sistemas agropecuários sustentáveis, ampliando a inserção da pesquisa paranaense em debates globais e trazendo benefícios diretos para o desenvolvimento rural e a segurança alimentar. | W12: 12 | X12: 6 | Y12: 4000 | Z12: 200 | AA12: 0 | AB12: 0 | AC12: 100 | AD12: 0 | AE12: 0 | AF12: Não | AG12: 0 | AH12: Não | AI12: =IF(AF12="Sim",INT((R12-Q12+1))*K12*VLOOKUP(P12,'Tabelas Auxiliares'!$A$1:$C$400,3,FALSE),0) -> 0 | AJ12: =(AG12/10)*7 -> 0 | AK12: =IFS( O12="Acre",((W12*0.15)+(X12*0.7))*VLOOKUP(P12,'MunicípiosEstados'!$A$2:$B$23,2,FALSE), O12="Alagoas",((W12*0.15)+(X12*0.7))*VLOOKUP(P12,'MunicípiosEstados'!$C$2:$D$103,2,FALSE), O12="Amapá",((W12*0.15)+(X12*0.7))*VLOOKUP(P12,'MunicípiosEstados'!$E$2:$F$17,2,FALSE), O12="Amazonas",((W12*0.15)+(X12*0.7))*VLOOKUP(P12,'MunicípiosEstados'!$G$2:$H$63,2,FALSE), O12="Bahia",((W12*0.15)+(X12*0.7))*VLOOKUP(P12,'MunicípiosEstados'!$I$2:$J$418,2,FALSE), O12="Ceará",((W12*0.15)+(X12*0.7))*VLOOKUP(P12,'MunicípiosEstados'!$K$2:$L$185,2,FALSE), O12="Distrito Federal",((W12*0.15)+(X12*0.7))*VLOOKUP(P12,'MunicípiosEstados'!$M$2:$N$2,2,FALSE), O12="Espírito Santo",((W12*0.15)+(X12*0.7))*VLOOKUP(P12,'MunicípiosEstados'!$O$2:$P$79,2,FALSE), O12="Goiás",((W12*0.15)+(X12*0.7))*VLOOKUP(P12,'MunicípiosEstados'!$Q$2:$R$247,2,FALSE), O12="Maranhão",((W12*0.15)+(X12*0.7))*VLOOKUP(P12,'MunicípiosEstados'!$S$2:$T$218,2,FALSE), O12="Mato Grosso",((W12*0.15)+(X12*0.7))*VLOOKUP(P12,'MunicípiosEstados'!$U$2:$V$143,2,FALSE), O12="Mato Grosso do Sul",((W12*0.15)+(X12*0.7))*VLOOKUP(P12,'MunicípiosEstados'!$W$2:$X$80,2,FALSE), O12="Minas Gerais",((W12*0.15)+(X12*0.7))*VLOOKUP(P12,'MunicípiosEstados'!$Y$2:$Z$854,2,FALSE), O12="Pará",((W12*0.15)+(X12*0.7))*VLOOKUP(P12,'MunicípiosEstados'!$AA$2:$AB$145,2,FALSE), O12="Paraíba",((W12*0.15)+(X12*0.7))*VLOOKUP(P12,'MunicípiosEstados'!$AC$2:$AD$224,2,FALSE), O12="Paraná",((W12*0.15)+(X12*0.7))*VLOOKUP(P12,'MunicípiosEstados'!$AE$2:$AF$400,2,FALSE), O12="Pernambuco",((W12*0.15)+(X12*0.7))*VLOOKUP(P12,'MunicípiosEstados'!$AG$2:$AH$186,2,FALSE), O12="Piauí",((W12*0.15)+(X12*0.7))*VLOOKUP(P12,'MunicípiosEstados'!$AI$2:$AJ$225,2,FALSE), O12="Rio Grande do Norte",((W12*0.15)+(X12*0.7))*VLOOKUP(P12,'MunicípiosEstados'!$AK$2:$AL$168,2,FALSE), O12="Rio Grande do Sul",((W12*0.15)+(X12*0.7))*VLOOKUP(P12,'MunicípiosEstados'!$AM$2:$AN$498,2,FALSE), O12="Rio de Janeiro",((W12*0.15)+(X12*0.7))*VLOOKUP(P12,'MunicípiosEstados'!$AO$2:$AP$93,2,FALSE), O12="Rondônia",((W12*0.15)+(X12*0.7))*VLOOKUP(P12,'MunicípiosEstados'!$AQ$2:$AR$53,2,FALSE), O12="Roraima",((W12*0.15)+(X12*0.7))*VLOOKUP(P12,'MunicípiosEstados'!$AS$2:$AT$16,2,FALSE), O12="Santa Catarina",((W12*0.15)+(X12*0.7))*VLOOKUP(P12,'MunicípiosEstados'!$AU$2:$AV$296,2,FALSE), O12="São Paulo",((W12*0.15)+(X12*0.7))*VLOOKUP(P12,'MunicípiosEstados'!$AW$2:$AX$646,2,FALSE), O12="Sergipe",((W12*0.15)+(X12*0.7))*VLOOKUP(P12,'MunicípiosEstados'!$AY$2:$AZ$76,2,FALSE), O12="Tocantins",((W12*0.15)+(X12*0.7))*VLOOKUP(P12,'MunicípiosEstados'!$BA$2:$BB$140,2,FALSE), O12="Exterior",((W12*0.15)+(X12*0.7))*VLOOKUP(P12,'MunicípiosEstados'!$BC$2:$BE$221,3,FALSE),TRUE,0 ) -> 13164.03 | AL12: =AK12+AJ12+AI12+AE12+AD12+AC12+AB12+AA12+Z12+Y12 -> 17464.03
